<?xml version="1.0"?>

<robot xmlns:xacro="http://ros.org/wiki/xacro">

  <xacro:include filename="inertial_macros.xacro"/>
  <xacro:include filename="materials.xacro"/>

  <link name="base_link"/>

  <link name="base_footprint">
  </link>
  <joint name="base_footprint_joint" type="fixed">
    <parent link="base_link"/>
    <child link="base_footprint"/>
    <origin xyz="0 0 0" rpy="0 0 0"/>
  </joint>

  <link name="chassis">
    <visual>
      <origin xyz="0.375 0 0.125"/>
      <geometry>
        <box size="1 0.5 0.25"/>
      </geometry>
      <material name="black"/>
    </visual>
    <collision>
      <origin xyz="0.375 0 0.125"/>
      <geometry>
        <box size="1 0.5 0.25"/>
      </geometry>
    </collision>
    <xacro:inertial_box mass="2" x="1" y="0.5" z="0.25">
      <origin xyz="0.375 0 0.125" rpy="0 0 0"/>
    </xacro:inertial_box>
  </link>
  <joint name="chassis_joint" type="fixed">
    <parent link="base_link"/>
    <child link="chassis"/>
    <origin xyz="-0.1 0 0"/>
  </joint>

  <link name="rear_left_wheel">
    <visual>
      <geometry>
        <cylinder radius="0.1" length="0.1"/>
      </geometry>
      <material name="gray"/>
    </visual>
    <collision>
      <geometry>
        <cylinder radius="0.1" length="0.1"/>
      </geometry>
    </collision>
    <xacro:inertial_cylinder mass="0.1" radius="0.1" length="0.1">
      <origin xyz="0 0 0" rpy="0 0 0"/>
    </xacro:inertial_cylinder>
  </link>
  <joint name="rear_left_wheel_joint" type="continuous">
    <parent link="base_link"/>
    <child link="rear_left_wheel"/>
    <origin xyz="0 0.3 0" rpy="-${pi/2} 0 0"/>
    <axis xyz="0 0 1"/>
  </joint>

  <link name="front_left_wheel">
    <visual>
      <geometry>
        <cylinder radius="0.1" length="0.1"/>
      </geometry>
      <material name="gray"/>
    </visual>
    <collision>
      <geometry>
        <cylinder radius="0.1" length="0.1"/>
      </geometry>
    </collision>
    <xacro:inertial_cylinder mass="0.1" radius="0.1" length="0.1">
      <origin xyz="0 0 0" rpy="0 0 0"/>
    </xacro:inertial_cylinder>
  </link>
  <joint name="front_left_wheel_joint" type="continuous">
    <parent link="base_link"/>
    <child link="front_left_wheel"/>
    <origin xyz="0.55 0.3 0" rpy="-${pi/2} 0 0"/>
    <axis xyz="0 0 1"/>
  </joint>

  <link name="front_right_wheel">
    <visual>
      <geometry>
        <cylinder radius="0.1" length="0.1"/>
      </geometry>
      <material name="gray"/>
    </visual>
    <collision>
      <geometry>
        <cylinder radius="0.1" length="0.1"/>
      </geometry>
    </collision>
    <xacro:inertial_cylinder mass="0.1" radius="0.1" length="0.1">
      <origin xyz="0 0 0" rpy="0 0 0"/>
    </xacro:inertial_cylinder>
  </link>
  <joint name="front_right_wheel_joint" type="continuous">
    <parent link="base_link"/>
    <child link="front_right_wheel"/>
    <origin xyz="0.55 -0.3 0" rpy="${pi/2} 0 0"/>
    <axis xyz="0 0 -1"/>
  </joint>

  <link name="rear_right_wheel">
    <visual>
      <geometry>
        <cylinder radius="0.1" length="0.1"/>
      </geometry>
      <material name="gray"/>
    </visual>
    <collision>
      <geometry>
        <cylinder radius="0.1" length="0.1"/>
      </geometry>
    </collision>
    <xacro:inertial_cylinder mass="0.1" radius="0.1" length="0.1">
      <origin xyz="0 0 0" rpy="0 0 0"/>
    </xacro:inertial_cylinder>
  </link>
  <joint name="rear_right_wheel_joint" type="continuous">
    <parent link="base_link"/>
    <child link="rear_right_wheel"/>
    <origin xyz="0 -0.3 0" rpy="${pi/2} 0 0"/>
    <axis xyz="0 0 -1"/>
  </joint>

</robot>
